Workbook
Name _GoBack: 'ПАК '!$E$18

Sheet Лист контроля  
H1: Лист результатов контроля технологического режима цеха № 66 (отделений Абсорбции-дистилляции-1, Карбонизации-1), цеха № 83 (отделения Кальцинации-1), цеха № 85 (отделения Компрессии-1) | AF1: страница 1 | AP1: =H1 -> Лист результатов контроля технологического режима цеха № 66 (отделений Абсорбции-дистилляции-1, Карбонизации-1), цеха № 83 (отделения Кальцинации-1), цеха № 85 (отделения Компрессии-1) | BN1: страница 1
A2: Расход промывной воды | E2: =F2+G2 -> 855 | F2: 428 | G2: 427 | AC2: Автоматический контроль КЛ | AG2: 21:00/5:00 | AI2: Расход промывной Н2О | AM2: =AN2+AO2 -> 865 | AN2: 425 | AO2: 440 | BK2: Автоматический контроль КЛ | BO2: 9:00/17:00 | CR2: Р 024-2023
A3: Расход очищенного рассола | F3: 4292 | H3: м3 | AC3: № кл | AD3: t, 0С суспензии на выходе из Кл | AE3: t, 0С отходящего газа после Кл | AF3: t, 0С 14 бочки | AG3: t, 0С 25 бочки | AI3: Расход очищенного рассола | AN3: 5236 | AP3: м3 | BK3: № кл | BL3: t, 0С суспензии на выходе из Кл | BM3: t, 0С отходящего газа после Кл | BN3: t, 0С 14 бочки | BO3: t, 0С 25 бочки | CN3: АО "БСК" | CR3: Приложение 3
A4: Расход по фильтровой жидкости | F4: 475 | H4: м3/ч | L4: Дата | N4: 04.03.2026г | Q4: Смена | S4: 1 | U4: Бригада | W4: А | AC4: 1 | AD4: 30 | AE4: 48 | AF4: 51 | AG4: 55 | AI4: Расход по фильтровой жидкости | AN4: 492 | AP4: м3/ч | AT4: Дата | AV4: =N4 -> 04.03.2026г | AY4: Смена | BA4: 2 | BC4: Бригада | BE4: в | BK4: 1 | BL4: 31 | BM4: 46 | BN4: 53 | BO4: 54 | BR4: АО "БСК" | BW4: Р 024-2023 | CN4: УАК лаборатория №4
A5: Расход химочищенной | F5: 272 | H5: м3 | AC5: 2 | AG5: 61 | AI5: Расход химочищенной | AN5: 275 | AP5: м3 | BK5: 2 | BL5: 29 | BM5: 46 | BN5: 55 | BO5: 55 | BR5: УАК Лаборатория № 3 | BW5: Приложение № 3 | CN5: Производство №5
B6: СТАНЦИЯ АБСОРБЦИИ | K6: СТАНЦИЯ КАРБОНИЗАЦИИ | AC6: 3 | AD6: 30 | AE6: 50 | AF6: 53 | AG6: 57 | AJ6: СТАНЦИЯ АБСОРБЦИИ | AS6: СТАНЦИЯ КАРБОНИЗАЦИИ | BK6: 3 | BL6: 30 | BM6: 50 | BN6: 56 | BO6: 59 | BR6: Производство № 4 | CN6: Цех № 83 отделение: Кальцинация 1 | CY6: =N4 -> 04.03.2026г
A7: Время | B7: Газ после ПВФЛ кол-р нагнетания | D7: Газ после ПГКл- II | G7: Аммонизированный рассол | K7: Жидкость после КлПК Об.экв.к.двуок.угл., н.д. | N7: Жидкость после ПГКл-1 Об.экв.к.двуок.угл., н.д. | Q7: Суспензия гидрокарбоната натрия 1 л/ф | U7: Суспензия гидрокарбоната натрия 2 л/ф | Y7: Суспензия гидрокарбоната натрия б/ф | AC7: 4 | AD7: 30 | AE7: 48 | AF7: 51 | AG7: 57 | AI7: Время | AJ7: Газ после ПВФЛ кол-р нагнетания | AL7: Газ после ПГКл- II | AO7: Аммонизированный рассол | AS7: Жидкость после КлПК Об.экв.к.двуок.угл., н.д. | AV7: Жидкость после ПГКл-1 Об.экв.к.двуок.угл., н.д. | AY7: Суспензия гидрокарбоната натрия 1 л/ф | BC7: Суспензия гидрокарбоната натрия 2 л/ф | BG7: Суспензия гидрокарбоната натрия б/ф | BK7: 4 | BL7: 29 | BM7: 46 | BN7: 54 | BO7: 59 | BR7: Цех № 66 | CY7: мин.знач. | DA7: макс.знач.
B8: № маш. | C8: М.к.аммиака (в пересчете на 25,5%), кг/т соды | D8: № эл. | E8: М.к.аммиака (в пересчете на 25,5%), кг/т соды | F8: Объёмная доля СО2, % | G8: Об.экв.к. сульфид-ионов, н.д | H8: Об.экв.к. двуок.угл., н.д. | I8: Об.экв.к. хлорид-ионов,н.д | J8: Общая щелочность (пр.т.), н.д | K8: 1гр. | L8: 2гр. | M8: 3гр. | N8: 1гр. | O8: 2гр. | P8: 3гр. | Q8: Об.экв.к. хлорид-ионов, н.д | R8: Общая щелочность (пр.т.), н.д | S8: Об.экв.к.ионов аммония, н.д | T8: Об.экв.к. NH₃ связ., н.д | U8: Об.экв.к. хлорид-ионов, н.д | V8: Общая щелочность (пр.т.), н.д | W8: Об.экв.к.ионов аммония, н.д | X8: Об.экв.к. NH₃ связ., н.д | Y8: Об.экв.к. хлорид-ионов, н.д | Z8: Общая щелочность (пр.т.), н.д | AA8: Об.экв.к.ионов аммония, н.д | AB8: Об.экв.к. NH₃ связ., н.д | AC8: 5 | AD8: 30 | AE8: 48 | AF8: 51 | AG8: 55 | AJ8: № маш. | AK8: М.к.аммиака (в пересчете на 25,5%), кг/т соды | AL8: № эл. | AM8: М.к.аммиака (в пересчете на 25,5%), кг/т соды | AN8: Объёмная доля СО2, % | AO8: Об.экв.к. сульфид-ионов, н.д | AP8: Об.экв.к. двуок.угл., н.д. | AQ8: Об.экв.к. хлорид-ионов,н.д | AR8: Общая щелочность (пр.т.), н.д | AS8: 1гр. | AT8: 2гр. | AU8: 3гр. | AV8: 1гр. | AW8: 2гр. | AX8: 3гр. | AY8: Об.экв.к. хлорид-ионов, н.д | AZ8: Общая щелочность (пр.т.), н.д | BA8: Об.экв.к.ионов аммония, н.д | BB8: Об.экв.к. NH₃ связ., н.д | BC8: Об.экв.к. хлорид-ионов, н.д | BD8: Общая щелочность (пр.т.), н.д | BE8: Об.экв.к.ионов аммония, н.д | BF8: Об.экв.к. NH₃ связ., н.д | BG8: Об.экв.к. хлорид-ионов, н.д | BH8: Общая щелочность (пр.т.), н.д | BI8: Об.экв.к.ионов аммония, н.д | BJ8: Об.экв.к. NH₃ связ., н.д | BK8: 5 | BO8: 60 | BR8: отделения: Карбонизации-1, Абсорбции-дистилляции-1 | CX8: NH3 ПВФл | CY8: =MIN(C11:C18,AK11:AK18,C25:C32,AK25:AK32) -> 0.06 | CZ8: - | DA8: =MAX(C11:C18,AK11:AK18,C25:C32,AK25:AK32) -> 0.24
A9: 20:00-21:00 | B9: время | D9: время | E9: 0.92361111 | F9: 0.95833333 | G9: 0.46 | I9: 88.1 | J9: 102.3 | K9: 66.9 | L9: 71.4 | M9: 61.8 | N9: 65.5 | O9: 75.7 | P9: 58.5 | Q9: 95.4 | R9: 26.6 | S9: 94.2 | T9: =S9-R9 -> 67.6 | U9: 95.4 | V9: 27 | W9: 94.6 | X9: =W9-V9 -> 67.6 | Y9: 95.4 | Z9: 26.6 | AA9: 94.6 | AB9: =AA9-Z9 -> 68 | AC9: 6 | AG9: 60 | AI9: 08:00-09:00 | AJ9: время | AL9: время | AM9: 0.48611111 | AO9: 0.56 | AQ9: 88.1 | AR9: 102.3 | AS9: 57.4 | AT9: 51.9 | AU9: 55.3 | AV9: 58.5 | AW9: 60.7 | AX9: 61 | AY9: 96.2 | AZ9: 28.6 | BA9: 97.8 | BB9: =BA9-AZ9 -> 69.2 | BC9: 96.6 | BD9: 28.6 | BE9: 97.4 | BF9: =BE9-BD9 -> 68.8 | BG9: 96.6 | BH9: 28.6 | BI9: 97.4 | BJ9: =BI9-BH9 -> 68.8 | BK9: 6 | BL9: 26 | BM9: 47 | BN9: 53 | BO9: 56 | CN9: СВЕДЕНИЯ О РАСХОДНЫХ КОЭФФИЦИЕНТАХ/АНАЛИТИЧЕСКИЕ ДАННЫЕ | CX9: Общ.щ. ПГКЛ-2 | CY9: =MIN(BL95:BL101) -> 0 | DA9: =MAX(BL95:BL101) -> 0
AC10: 7 | AD10: 31 | AE10: 49 | AF10: 51 | AG10: 55 | BK10: 7 | BL10: 31 | BM10: 48 | BN10: 56 | BO10: 60 | CX10: СО2 ПГКл-2 | CY10: =MIN(F11:F22,AN11:AN22,F25:F34,AN25:AN34) -> 0 | CZ10: - | DA10: =MAX(F11:F22,AN11:AN22,F25:F34,AN25:AN34) -> 0
A11: 21:00-22:00 | B11: 1 | D11: 1 | E11: 0.06 | F11: загаз. | J11: 103.1 | U11: н.тех.п. | AC11: 8 | AD11: 28 | AE11: 52 | AF11: 43 | AG11: 53 | AI11: 09:00-10:00 | AJ11: 1 | AL11: 1 | AM11: 0.2 | AR11: 102 | BK11: 8 | BO11: 61 | CX11: NH3 ПГКл-2 | CY11: =MIN(E11:E22,AM11:AM22,E25:E34,AM25:AM34) -> 0.06 | CZ11: - | DA11: =MAX(E11:E22,AM11:AM22,E25:E34,AM25:AM34) -> 0.2
AC12: 9 | AD12: 30 | AE12: 49 | AF12: 53 | AG12: 55 | BK12: 9 | BL12: 30 | BM12: 50 | BN12: 57 | BO12: 58 | CN12: на производство кальцинированной соды марки "Б" | CX12: СО2 после ПГАБ | CY12: =MIN(AC78:AC89,BK78:BK89) -> 81 | CZ12: - | DA12: =MAX(AC78:AC89,BK78:BK89) -> 89
A13: 22:00-23:00 | B13: 2 | C13: 0.06 | D13: 2 | E13: 0.06 | F13: загаз. | J13: 102.7 | AC13: 10 | AD13: 30 | AE13: 49 | AF13: 45 | AG13: 50 | AI13: 10:00-11:00 | AJ13: 2 | AK13: 0.12 | AL13: 2 | AM13: загаз | AR13: 102.3 | BK13: 10 | BL13: 31 | BM13: 47 | BN13: 49 | BO13: 53 | CX13: Общ.щ. ПГАБ | CY13: =MIN(BM95:BM101) -> 0 | CZ13: - | DA13: =MAX(BM95:BM101) -> 0
AC14: 11 | BK14: 11 | CX14: Т0 ХГДС | CY14: =MIN(AC40:AC46,AC48:AC54,BK40:BK46,BK48:BK54) -> 55 | CZ14: - | DA14: =MAX(AC40:AC46,AC48:AC54,BK40:BK46,BK48:BK54) -> 89
A15: 23:00-24:00 | B15: 3 | C15: 0.06 | D15: 3 | E15: 0.06 | F15: загаз. | J15: 102 | U15: н.тех.п. | AC15: 12 | AG15: 58 | AI15: 11:00-12:00 | AJ15: 3 | AK15: 0.12 | AL15: 3 | AM15: загаз | AR15: 103.9 | BK15: 12 | BO15: 58 | BR15: СВЕДЕНИЯ О РАСХОДНЫХ КОЭФФИЦИЕНТАХ / АНАЛИТИЧЕСКИЕ ДАННЫЕ | CO15: за | CP15: =N4 -> 04.03.2026г | CX15: Об.щ. САР | CY15: =MIN(J9:J34,AR9:AR34) -> 100 | CZ15: - | DA15: =MAX(J9:J34,AR9:AR34) -> 104.3
AC16: 13 | AD16: 30 | AE16: 50 | AF16: 54 | AG16: 55 | BK16: 13 | BL16: 29 | BM16: 48 | BN16: 56 | BO16: 56 | CX16: СL⁻ Сара | CY16: =MIN(I9:I35,AQ9:AQ35) -> 88.1 | CZ16: - | DA16: =MAX(I9:I35,AQ9:AQ35) -> 88.5
A17: 00:00-01:00 | B17: 4 | C17: 0.06 | D17: 5 | E17: 0.06 | F17: загаз. | J17: 103.5 | K17: пер | L17: пер | M17: 67.7 | N17: 68.8 | O17: 67.4 | P17: 67.9 | Q17: 95 | R17: 29 | S17: 96.6 | T17: =S17-R17 -> 67.6 | U17: 95 | V17: 30.2 | W17: 96.6 | X17: =W17-V17 -> 66.4 | Y17: 95.4 | Z17: 29.8 | AA17: 97 | AB17: =AA17-Z17 -> 67.2 | AC17: 14 | AI17: 12:00-13:00 | AJ17: 4 | AK17: 0.24 | AL17: 5 | AM17: загаз | AR17: 104.3 | BK17: 14 | CX17: S Сара | CY17: =MIN(G9:G34,AO9:AO34) -> 0.4 | CZ17: - | DA17: =MAX(G9:G34,AO9:AO34) -> 0.56
AC18: 15 | AD18: 30 | AE18: 47 | AF18: 50 | AG18: 52 | BK18: 15 | BL18: 31 | BM18: 46 | BN18: 51 | BO18: 52 | BU18: =N4 -> 04.03.2026г | CX18: Т0 Сара | CY18: =MIN(F73,AN73) -> 62 | CZ18: - | DA18: =MAX(F73,AN73) -> 64
A19: 01:00-02:00 | D19: 7 | J19: 102.7 | U19: н.тех.п. | AC19: 1 | AD19: 31 | AE19: 52 | AF19: 45 | AG19: 50 | AI19: 13:00-14:00 | AL19: 7 | AR19: 103.9 | BK19: 1 | BL19: 31 | BM19: 47 | BN19: 53 | BO19: 57 | BT19: за | CN19: Наименование сырья, основных и вспомогательных материалов | CP19: Расходные коэффициенты
AC20: 2 | AD20: 29 | AE20: 49 | AF20: 50 | AG20: 55 | BK20: 2 | BL20: 34 | BM20: 44 | BN20: 58 | BO20: 57 | CX20: Т0 КДС | CY20: =MIN(AB40:AB46,AB48:AB54,BJ40:BJ46,BJ48:BJ54) -> 67 | CZ20: - | DA20: =MAX(AB40:AB46,AB48:AB54,BJ40:BJ46,BJ48:BJ54) -> 90
A21: 02:00-03:00 | B21: 5 | C21: 0.06 | G21: 0.4 | I21: 88.1 | J21: 102.7 | AC21: 3 | AD21: 30 | AE21: 50 | AF21: 54 | AG21: 57 | AI21: 14:00-15:00 | AJ21: 5 | AK21: 0.36 | AO21: 0.42 | AQ21: 88.5 | AR21: 100 | AS21: 61.1 | AT21: 58.2 | AU21: 61.2 | AZ21: 30.2 | BA21: 98.2 | BB21: =BA21-AZ21 -> 68 | BD21: 29.8 | BE21: 98.2 | BF21: =BE21-BD21 -> 68.4 | BH21: 29.4 | BI21: 101.1 | BJ21: =BI21-BH21 -> 71.7 | BK21: 3 | BL21: 30 | BM21: 46 | BN21: 58 | BO21: 59 | CP21: l смена | CR21: ll смена | CX21: NH3 ДСЖ | CY21: =MIN(U40:U53,W40:W53,BC40:BC53,BE40:BE53) -> 4 | CZ21: - | DA21: =MAX(U40:U53,W40:W53,BC40:BC53,BE40:BE53) -> 8
AC22: 4 | AD22: 30 | AE22: 52 | AF22: 50 | AG22: 59 | BK22: 4 | BL22: 31 | BM22: 45 | BN22: 56 | BO22: 60 | BR22: Наименование сырья, основных и вспомогательных материалов | BT22: Расходные коэффициенты | CX22: NH3 ИС | CY22: =MIN(P40:P46,P48:P54,S40:S53,AX40:AX46,AX48:AX54,BA40:BA53) -> 4 | CZ22: - | DA22: =MAX(P40:P46,P48:P54,S40:S53,AX40:AX46,AX48:AX54,BA40:BA53) -> 10.8
A23: 03:00-04:00 | B23: время | D23: время | J23: 102 | U23: н.тех.п. | AC23: 5 | AG23: 60 | AI23: 15:00-16:00 | AJ23: время | AL23: время | AR23: 102 | BK23: 5 | BO23: 55 | CP23: (с 20:00 часов | CR23: (с 08:00 часов | CX23: СаО ИС | CY23: =MIN(AW40:AW46,AW48:AW54,AZ40:AZ53,O40:O46,O48:O54,R40:R53) -> 1.4 | CZ23: - | DA23: =MAX(AW40:AW46,AW48:AW54,AZ40:AZ53,O40:O46,O48:O54,R40:R53) -> 3.2
AC24: 6 | AD24: 27 | AE24: 46 | AF24: 54 | AG24: 54 | BK24: 6 | BL24: 31 | BM24: 45 | BN24: 57 | BO24: 57 | BT24: l смена | BV24: ll смена | CX24: СL ДС | CY24: =MIN(Q40:Q46,Q48:Q54,AY40:AY46,AY48:AY54) -> 60.9 | CZ24: - | DA24: =MAX(Q40:Q46,Q48:Q54,AY40:AY46,AY48:AY54) -> 65.7
A25: 04:00-05:00 | B25: 1 | J25: 102.7 | AC25: 7 | AD25: 31 | AE25: 52 | AF25: 54 | AG25: 58 | AI25: 16:00-17:00 | AJ25: 1 | AR25: - | BK25: 7 | BL25: 31 | BM25: 48 | BN25: 58 | BO25: 61 | CP25: до 08:00 часов) | CR25: до 20:00 часов) | CX25: СО2 ТДС | CY25: =MIN(Y40:Y54,BG40:BG54) -> 0.36 | CZ25: - | DA25: =MAX(Y40:Y54,BG40:BG54) -> 1.5
AC26: 8 | AG26: 61 | BK26: 8 | BO26: 58 | BT26: (с 20:00 часов | BV26: (с 08:00 часов
A27: 05:00-06:00 | B27: 2 | J27: 102.7 | U27: н.тех.п. | AC27: 9 | AD27: 31 | AE27: 52 | AF27: 54 | AG27: 57 | AI27: 17:00-18:00 | AJ27: 2 | AR27: 102.3 | BK27: 9 | BL27: 30 | BM27: 48 | BN27: 58 | BO27: 57 | CN27: М.д. углекислого натрия, ( Na2CO3)% в соде кальцинированной марки Б с технологических ниток: -после содовых печей рейдлер Р2,Р2а,р2б (поз.921-3) отм. 0,0 м. | CP27: =AVERAGE(C95:C106,G95:G106,K95:K106) -> 99.33 | CR27: =AVERAGE(AK95:AK106,AO95:AO106,AS95:AS106) -> 99.33 | CX27: Связ. NH3 Кл | CY27: =MIN(T9:T33,X9:X33,AB9:AB33,BB9:BB33,BF9:BF33,BJ9:BJ33) -> 66.4 | CZ27: - | DA27: =MAX(T9:T33,X9:X33,AB9:AB33,BB9:BB33,BF9:BF33,BJ9:BJ33) -> 71.7
AC28: 10 | AD28: 29 | AE28: 48 | AF28: 39 | AG28: 45 | BK28: 10 | BL28: 30 | BM28: 50 | BN28: 49 | BO28: 55 | BT28: до 08:00 часов) | BV28: до 20:00 часов) | CX28: СL Кл. | CY28: =MIN(Q9:Q33,U9:U33,Y9:Y33,AY9:AY33,BC9:BC33,BG9:BG33) -> 95 | CZ28: - | DA28: =MAX(Q9:Q33,U9:U33,Y9:Y33,AY9:AY33,BC9:BC33,BG9:BG33) -> 98.6
A29: 06:00-07:00 | B29: 3 | J29: 102.3 | L29: =ROUND(AVERAGE(K9:M28),1) -> 67 | O29: =ROUND(AVERAGE(N9:P28),1) -> 67.3 | AC29: 11 | AI29: 18:00-19:00 | AJ29: 3 | AR29: 103.5 | AT29: =ROUND(AVERAGE(AS9:AU28),1) -> 57.5 | AW29: =ROUND(AVERAGE(AV9:AX28),1) -> 60.1 | BK29: 11 | CX29: Т0 сусп Кл | CY29: =MIN(AD4:AD33,BL4:BL33) -> 26 | CZ29: - | DA29: =MAX(AD4:AD33,BL4:BL33) -> 34
K30: Температура жидкости КлПК,˚С | N30: Температура жидкости ПГКл -1,˚С | AC30: 12 | AG30: 58 | AS30: Температура жидкости КлПК,˚С | AV30: Температура жидкости ПГКл -1,˚С | BK30: 12 | BO30: 55 | BR30: Расход рассола очищенного в пересчёте на стандартный рассол с содержанием NaCl 310 г/л, (м3/т.соды) | BT30: =B131 -> 5.789 | BV30: =AJ131 -> 5.875 | CX30: Т0 верха Кл | CY30: =MIN(AE4:AE33,BM4:BM33) -> 44 | CZ30: - | DA30: =MAX(AE4:AE33,BM4:BM33) -> 52
A31: 07:00-08:00 | B31: 4 | J31: 103.1 | K31: 54 | L31: 68 | M31: 72 | N31: 36 | O31: 38 | P31: 38 | U31: н.тех.п. | AC31: 13 | AD31: 30 | AE31: 49 | AF31: 55 | AG31: 56 | AI31: 19:00-20:00 | AJ31: 4 | AR31: - | AS31: 63 | AT31: 61 | AU31: 71 | AV31: 41 | AW31: 39 | AX31: 39 | BK31: 13 | BL31: 30 | BM31: 48 | BN31: 57 | BO31: 56 | CX31: СО2 КЛПК | CY31: =MIN(K9:M28,AS9:AU28) -> 51.9 | CZ31: - | DA31: =MAX(K9:M28,AS9:AU28) -> 71.4
AC32: 14 | BK32: 14 | CN32: % соды с м.д хлоридов в пересчете на NaCl не более 0,5% от общей выработки соды кальцинированной марки Б с технологических ниток : после содовых печей рейдлер Р2,Р2а,р2б (поз.921-3) отм. 0,0 м. | CP32: =CQ70 -> #DIV/0! | CR32: =CQ71 -> #DIV/0! | CX32: СО2 1 вход | CY32: =MIN(AD78:AE89,BL78:BM89) -> 50 | CZ32: - | DA32: =MAX(AD78:AE89,BL78:BM89) -> 59
B33: 5 | L33: =ROUND(AVERAGE(K31:M32),0) -> 65 | O33: =ROUND(AVERAGE(N31:P32),0) -> 37 | Q33: 95.8 | R33: 29.8 | S33: 97.4 | T33: =ROUND((S33-R33),1) -> 67.6 | U33: 96.6 | V33: 29.8 | W33: 97.8 | X33: =ROUND((W33-V33),1) -> 68 | Y33: 95.8 | Z33: 29.8 | AA33: 98.2 | AB33: =ROUND((AA33-Z33),1) -> 68.4 | AC33: 15 | AD33: 31 | AE33: 49 | AF33: 51 | AG33: 55 | AJ33: 5 | AT33: =ROUND(AVERAGE(AS31:AU32),0) -> 65 | AW33: =ROUND(AVERAGE(AV31:AX32),0) -> 40 | AY33: 97.8 | AZ33: 27.8 | BA33: 97.8 | BB33: =ROUND((BA33-AZ33),1) -> 70 | BC33: 98.6 | BD33: 27.8 | BE33: 97.8 | BF33: =ROUND((BE33-BD33),1) -> 70 | BG33: 98.6 | BH33: 27.8 | BI33: 98.6 | BJ33: =ROUND((BI33-BH33),1) -> 70.8 | BK33: 15 | BL33: 31 | BM33: 49 | BN33: 51 | BO33: 55
R34: Об.экв.к.двуок.угл. н.д. | T34: 43.7 | V34: Об.экв.к.двуок.угл. н.д. | X34: 42.3 | Y34: Об.экв.к. двуок.угл.,н.д. | Z34: % уноса аммиака | AA34: Об.экв.к. двуок.угл.,н.д. | AB34: 42.1 | AC34: ср.зн. | AD34: =ROUND(AVERAGE(AD4:AD33),) -> 30 | AE34: =ROUND(AVERAGE(AE4:AE33),) -> 49 | AF34: =ROUND(AVERAGE(AF4:AF33),) -> 50 | AG34: =ROUND(AVERAGE(AG4:AG33),) -> 56 | AS34: Об.экв.к.хлорид-ионов, н.д | AT34: Общая щелочность (пр.т.), н.д | AU34: Об.экв.к.ионов аммония,н.д | AV34: Об.экв.к.хлорид-ионов, н.д | AW34: Общая щелочность (пр.т.), н.д | AX34: Об.экв.к.ионов аммония,н.д | AZ34: Об.экв.к.двуок.угл. н.д. | BB34: 35.5 | BD34: Об.экв.к.двуок.угл. н.д. | BF34: 36.9 | BG34: Об.экв.к. двуок.угл.,н.д. | BH34: % уноса аммиака | BI34: Об.экв.к. двуок.угл.,н.д. | BJ34: 37 | BK34: ср.зн. | BL34: =ROUND(AVERAGE(BL4:BL33),) -> 30 | BM34: =ROUND(AVERAGE(BM4:BM33),) -> 47 | BN34: =ROUND(AVERAGE(BN4:BN33),) -> 55 | BO34: =ROUND(AVERAGE(BO4:BO33),) -> 57 | BR34: Массовая концентрация хлорид-ионов в жидкости САР, (н.д.) | BT34: =I35 -> 88.1 | BV34: =AQ35 -> 88.5 | CX34: W б/ф | CY34: =MIN(G78:G89,AO78:AO89) -> 15 | CZ34: - | DA34: =MAX(G78:G89,AO78:AO89) -> 20.5
A35: ср.зн. | C35: =ROUND(AVERAGE(C11:C18,C25:C32),2) -> 0.06 | E35: =ROUND(AVERAGE(E11:E22,E25:E34),2) -> 0.06 | F35: =ROUND(AVERAGE(F11:F22,F25:F34),1) -> #DIV/0! | G35: =ROUND(AVERAGE(G9:G32),2) -> 0.43 | H35: 45.2 | I35: 88.1 | J35: =ROUND(AVERAGE(J9:J32),1) -> 102.7 | U35: =ROUND(AVERAGE(Q33,U33,Y33),1) -> 96.1 | V35: =ROUND(AVERAGE(R33,V33,Z33),1) -> 29.8 | W35: =ROUND(AVERAGE(S33,W33,AA33),1) -> 97.8 | X35: =ROUND((W35-V35),1) -> 68 | Y35: =ROUND(AVERAGE(T34,X34,AB34),1) -> 42.7 | Z35: =(1-((W35*I35)/(J35*U35)))*100 -> 12.698656 | AD35: =COUNT(AD4:AD33) -> 20 | AI35: ср.зн. | AK35: =ROUND(AVERAGE(AK11:AK18,AK25:AK32),2) -> 0.16 | AM35: =ROUND(AVERAGE(AM11:AM22,AM25:AM34),2) -> 0.2 | AN35: =ROUND(AVERAGE(AN11:AN22,AN25:AN34),1) -> #DIV/0! | AO35: =ROUND(AVERAGE(AO9:AO34),2) -> 0.49 | AP35: 40.7 | AQ35: 88.5 | AR35: =ROUND(AVERAGE(AR9:AR34),1) -> 102.7 | AS35: 87.3 | AT35: 96.3 | AU35: 95.8 | AV35: 87.3 | AW35: 97.9 | AX35: 98.2 | BC35: =ROUND(AVERAGE(AY33,BC33,BG33),1) -> 98.3 | BD35: =ROUND(AVERAGE(AZ33,BD33,BH33),1) -> 27.8 | BE35: =ROUND(AVERAGE(BA33,BE33,BI33),1) -> 98.1 | BF35: =ROUND((BE35-BD35),1) -> 70.3 | BG35: =ROUND(AVERAGE(BB34,BF34,BJ34),1) -> 36.5 | BH35: =(1-((BE35*AQ35)/(AR35*BC35)))*100 -> 14.002007 | BL35: =COUNT(BL4:BL33) -> 20 | CX35: СL б/ф | CY35: =MIN(M78:T89,AU78:BB89) -> 0.06 | CZ35: - | DA35: =MAX(M78:T89,AU78:BB89) -> 0.07
N36: СТАНЦИЯ ДИСТИЛЛЯЦИИ | AV36: СТАНЦИЯ ДИСТИЛЛЯЦИИ | CX36: W л/ф | CY36: =MIN(E78:F89,AM78:AN89) -> 12.9 | CZ36: - | DA36: =MAX(E78:F89,AM78:AN89) -> 19.7
A37: Усредненные прбы за смену | B37: Об.экв.к.хлорид-ионов, н.д | C37: Общая щелоч-ность (пр.т.), н.д | D37: Об.экв.к.ионов аммония,н.д | E37: Об.экв.к.NH₃ связ, н.д | F37: Об.экв.к.двуок.угл.,н.д. | G37: Маточная жидкость с в/ф | J37: Фильтровая жидкость из СФЖ | N37: Жидкость после ИС | R37: Дистиллерная жидкость шламопровода | U37: Жидкость после дистиллера слабой жидкости (ДСЖ № 1 ) | W37: Жидкость после дистиллера флегмы (ДСЖ № 2 ) | Y37: Жидкость после ТДС | Z37: Автоматический контроль АБ-ДС | AG37: Время | AI37: Усредненные прбы за смену | AJ37: Об.экв.к.хлорид-ионов, н.д | AK37: Общая щелоч-ность (пр.т.), н.д | AL37: Об.экв.к.ионов аммония,н.д | AM37: Об.экв.к.NH₃ связ, н.д | AN37: Об.экв.к.двуок.угл.,н.д. | AO37: Маточная жидкость с в/ф | AR37: Фильтровая жидкость из СФЖ | AV37: Жидкость после ИС | AZ37: Дистиллерная жидкость шламопровода | BC37: Жидкость после дистиллера слабой жидкости (ДСЖ № 1 ) | BE37: Жидкость после дистиллера флегмы (ДСЖ № 2 ) | BG37: Жидкость после ТДС | BH37: Автоматический контроль АБ-ДС | BO37: Время | BR37: Расход извести в пересчёте на 85% СаО, (кг/т.соды) | BT37: =B132 -> 730.871 | BV37: =AJ132 -> 711.694 | CN37: % соды с м.д хлоридов в пересчете на NaCl не более 0,5% от общей выработки соды кальцинированной марки Б с технологических ниток : после паровых кальцинаторов редлер 4б (поз.128) отм.10.3 м. | CP37: =CU70 -> 0 | CR37: =CU71 -> 0 | CX37: СL л/ф | CY37: =MIN(K78:L89,AS78:AT89) -> 0.06 | CZ37: - | DA37: =MAX(K78:L89,AS78:AT89) -> 0.27
G38: Об.экв.к.хлорид-ионов,н.д | J38: Об.экв.к. хлорид-ионов, н.д | K38: Общая щелочность (пр.т.), н.д | L38: Об.экв.к.ионов аммония,н.д | M38: Об.экв.к.NH₃ связ., н.д | N38: № эл. | O38: Об.экв.к.акт.гидрокс.кальц.в пер.на акт.окись кальц.(СаОакт), н.д | P38: Об.экв.к.аммиака, н.д/2л | Q38: Об.экв.к. хлорид-ионов, н.д | R38: Об.экв.к.акт.гидрокс.кальц.в пер.на акт.окись кальц.(СаОакт), н.д | S38: Об.экв.к.аммиака, н.д/2л | T38: Об.экв.к. хлорид-ионов, н.д | U38: Об.экв.к.аммиака, н.д/2л | V38: Об.экв.к. хлорид-ионов, н.д | W38: Об.экв.к.аммиака, н.д/2л | X38: Об.экв.к. хлорид-ионов, н.д | Y38: Об.экв.к.двуок.угл., н.д. | Z38: № | AA38: t газовой смеси на выходе из ДС ,0C | AB38: t газовой смеси на выходе из КДС,0C | AC38: t газовой смеси на выходе из ХГДС,0C | AD38: t газа на выходе из АБ1/АБ2,0C | AE38: Р в нижней зоне ДС,кгс/см2 | AF38: Расход ФЖ на элемент ДС,м3/ч | AO38: Об.экв.к.хлорид-ионов,н.д | AR38: Об.экв.к. хлорид-ионов, н.д | AS38: Общая щелочность (пр.т.), н.д | AT38: Об.экв.к.ионов аммония,н.д | AU38: Об.экв.к.NH₃ связ., н.д | AV38: № эл. | AW38: Об.экв.к.акт.гидрокс.кальц.в пер.на акт.окись кальц.(СаОакт), н.д | AX38: Об.экв.к.аммиака, н.д/2л | AY38: Об.экв.к. хлорид-ионов, н.д | AZ38: Об.экв.к.акт.гидрокс.кальц.в пер.на акт.окись кальц.(СаОакт), н.д | BA38: Об.экв.к.аммиака, н.д/2л | BB38: Об.экв.к. хлорид-ионов, н.д | BC38: Об.экв.к.аммиака, н.д/2л | BD38: Об.экв.к. хлорид-ионов, н.д | BE38: Об.экв.к.аммиака, н.д/2л | BF38: Об.экв.к. хлорид-ионов, н.д | BG38: Об.экв.к.двуок.угл., н.д. | BH38: № | BI38: t газовой смеси на выходе из ДС ,0C | BJ38: t газовой смеси на выходе из КДС,0C | BK38: t газовой смеси на выходе из ХГДС,0C | BL38: t газа на выходе из АБ1/АБ2,0C | BM38: Р в нижней зоне ДС,кгс/см2 | BN38: Расход ФЖ на элемент ДС,м3/ч | CX38: Потери л/ф | CY38: =MIN(D47:D48,AL47:AL48) -> 6.2 | CZ38: - | DA38: =MAX(D47:D48,AL47:AL48) -> 10.3
G39: 1л/ф | H39: 2 л/ф | I39: б/ф | Z39: эл. | AO39: 1л/ф | AP39: 2 л/ф | AQ39: б/ф | BH39: эл. | CX39: СL МЖ л/ф | CY39: =MIN(G40:H51,B40:B41,AJ40:AJ41,AO40:AP51) -> 84.1 | CZ39: - | DA39: =MAX(G40:H51,B40:B41,AJ40:AJ41,AO40:AP51) -> 90.1
A40: МЖ 1л/ф | B40: 85.7 | C40: 32.6 | D40: 89 | E40: =D40-C40 -> 56.4 | F40: 44 | G40: 85.7 | H40: 86.1 | I40: 74.5 | J40: 80.9 | K40: 28.6 | L40: 80.9 | M40: =L40-K40 -> 52.3 | N40: 2 | O40: 3.2 | P40: 4.8 | Q40: 64.1 | R40: 3 | S40: 4.4 | T40: 61.7 | U40: 4 | V40: 0.04 | W40: 6 | X40: 0.08 | Z40: 1 | AC40: 60 | AD40: 62 | AG40: 0.875 | AI40: МЖ 1л/ф | AJ40: 89.7 | AK40: 31.8 | AL40: 89.4 | AM40: =AL40-AK40 -> 57.6 | AN40: 40.6 | AO40: 88.9 | AP40: 88.9 | AQ40: 78.5 | AR40: 82.5 | AS40: 32.2 | AT40: 83.3 | AU40: =AT40-AS40 -> 51.1 | AV40: =N40 -> 2 | AW40: 2.6 | AX40: 4.8 | AY40: 64.1 | AZ40: 1.4 | BA40: 6.8 | BB40: 64.1 | BC40: 4 | BD40: 0.06 | BE40: 8 | BF40: 0.12 | BH40: 1 | BK40: 62 | BL40: 64 | BO40: 0.375 | BR40: Расход промывной воды на ленточные вакуум-фильтры, (м³/т.соды) | BT40: =BU78 -> 1.054 | BV40: =BU79 -> 0.891 | CX40: Потери б/ф | CY40: =MIN(AF60,BN60) -> 14.6 | CZ40: - | DA40: =MAX(AF60,BN60) -> 15.7
...

Sheet Доп.анализы

Sheet Анализ возд.среды 
A1: Время замера | B1: Цех № 66 Отделение Карбонизации-1 | K1: Отделение АД-1
B2: отметка 0,0м | E2: отметка 8,0м | H2: отметка 12,0м | K2: отм.8,0 | L2: отм.32,0 | M2: отм.46,0
B3: NH3, мг/м3 | C3: H2S, мг/м3 | D3: СО, мг/м3 | E3: NH3, мг/м3 | F3: H2S, мг/м3 | G3: СО, мг/м3 | H3: NH3, мг/м3 | I3: H2S, мг/м3 | J3: СО, мг/м3 | K3: NH3, мг/м3 | L3: NH3, мг/м3 | M3: NH3, мг/м3
A4: 0.35416667 | B4: 71 | C4: 0.4 | D4: 4 | E4: 80 | F4: 0.6 | G4: 9 | H4: 82 | I4: 0.8 | J4: 11 | K4: не работает лифт | O4: =K4 -> не работает лифт | P4: =L4 -> 0 | Q4: =M4 -> 0 | R4: =B4 -> 71 | S4: =E4 -> 80 | T4: =H4 -> 82
A8: дата | B8: Время замера | C8: Отделение Кальцинации - 1
C10: Прожектеры отм.5,38 | E10: Задавалка отм.10,3
C11: NH3, мг/м3 | D11: CO, мг/м3 | E11: NH3, мг/м3 | F11: CO, мг/м3
A12: 46085 | B12: 0.35416667 | C12: 55 | D12: 0 | E12: 57 | F12: 0
A16: Дата | B16: Время замера | C16: Наименование аппарата | F16: № наряда-допуска | H16: NH3, мг/м3 | I16: H2S, мг/м3 | J16: СО, мг/м3 | K16: О2 %
A17: 46085 | B17: 0.33333333 | C17: АД-1, ДС эл№1, отм.16,0м | F17: 19 | H17: 42 | I17: 0.2 | J17: 4 | K17: 20.9
A18: 46085 | B18: 0.33680556 | C18: АД-1, СМ эл№1, отм.16,0м | F18: 17 | H18: 67 | I18: 0.2 | J18: 4 | K18: 20.9
A19: 46085 | B19: 0.35416667 | C19: СП 4 | F19: 874 | H19: 20 | J19: 0 | K19: 20.8
A20: 46085 | B20: 0.35416667 | C20: СП 4 | F20: 279 | H20: 20 | J20: 0 | K20: 20.8
A21: 46085 | B21: 0.53819444 | C21: АД-1, ДС эл№1, отм.16,0м | F21: 19 | H21: 56 | I21: 0.2 | J21: 5 | K21: 20.9
A22: 46085 | B22: 0.54166667 | C22: АД-1, СМ эл№1, отм.16,0м | F22: 17 | H22: 105 | I22: 0.2 | J22: 7 | K22: 20.9

Sheet Декадные анализы
A1: Дата | B1: № эле-мента | C1: Жидк. после ПГКл-2 | E1: Жидк. после ПГАБ | G1: Выходящая жидкость из КДС | N1: Флегма (конденсат) после КДС
C2: Объем HCL =1моль/дм³ израсходо-ванный на титрование, см³ | D2: Общая щелоч-ность (пр.т.), н.д. | E2: Объем HCL =1моль/дм³ израсходо-ванный на титрование, см³ | F2: Общая щелочность (пр.т.), н.д. | G2: Объем Hg(NO₃)₂= 0,1моль/дм³, израсходова-нный на титрование, см³ | H2: Об.экв. концентра-ция хлорид-ионов, н.д. | I2: Объем HCL =1моль/дм³ израсходо-ванный на титрование, см³ | J2: Общая щелочность (пр.т.), н.д. | K2: Объем HCL =1моль/дм³ израсходо-ванный на титрование, см³ | L2: Об.экв. концент-рация ионов аммония, н.д. | M2: Об.экв. концентра-ция NH₃ связан,н.д | N2: Объем Hg(NO₃)₂= 0,1моль/дм³, израсходова-нный на титрование, см³ | O2: Об.экв. концентра-ция хлорид-ионов, н.д. | P2: Объем HCL =1моль/дм³ израсходо-ванный на титрование, см³ | Q2: Общая щелочность (пр.т.), н.д. | R2: Объем HCL =1моль/дм³ израсходо-ванный на титрование, см³ | S2: Об.экв. концент-рация ионов аммония, н.д. | T2: Об.экв. концентра-ция NH₃ связан,н.д
B3: № 1 | M3: =L3-J3 -> 0 | T3: =S3-Q3 -> 0
B4: № 2 | M4: =L4-J4 -> 0 | T4: =S4-Q4 -> 0
B5: № 3 | M5: =L5-J5 -> 0 | T5: =S5-Q5 -> 0
B6: № 4 | M6: =L6-J6 -> 0 | T6: =S6-Q6 -> 0
B7: № 5 | M7: =L7-J7 -> 0 | T7: =S7-Q7 -> 0
B8: № 6 | M8: =L8-J8 -> 0 | T8: =S8-Q8 -> 0
B9: № 7 | M9: =L9-J9 -> 0 | T9: =S9-Q9 -> 0
D10: =AVERAGE(D3:D9) -> #DIV/0! | F10: =AVERAGE(F3:F9) -> #DIV/0! | H10: =AVERAGE(H3:H9) -> #DIV/0! | J10: =AVERAGE(J3:J9) -> #DIV/0! | L10: =AVERAGE(L3:L9) -> #DIV/0! | M10: =AVERAGE(M3:M9) -> 0 | O10: =AVERAGE(O3:O9) -> #DIV/0! | Q10: =AVERAGE(Q3:Q9) -> #DIV/0! | S10: =AVERAGE(S3:S9) -> #DIV/0! | T10: =AVERAGE(T3:T9) -> 0

Sheet Анализы на период ОКР
A1: Коллектор отходящей воды: Массовая концентрация аммиака и ионов аммония в пересчёте на ион аммония, мг/дм3
A2: Дата: | D2: Смена | E2: 1 | H2: Бригада
A4: Время | B4: 1059 | C4: 1-2гр. | D4: 3гр. | E4: 4гр. | F4: 4К | G4: отм.0.0 | H4: 12 | I4: 1859 | J4: 223А | K4: об.в.
A5: 0.83333333
A6: 0.875
A7: 0.91666667
A8: 0.95833333
A9: 1
A10: 1.0416667
A11: 1.0833333
A12: 1.125
A13: 1.1666667
A14: 1.2083333
A15: 1.25
A16: 1.2916667
A17: ср.знач. | B17: =AVERAGE(B5:B16) -> #DIV/0! | C17: =AVERAGE(C5:C16) -> #DIV/0! | D17: =AVERAGE(D5:D16) -> #DIV/0! | E17: =AVERAGE(E5:E16) -> #DIV/0! | F17: =AVERAGE(F5:F16) -> #DIV/0! | G17: =AVERAGE(G5:G16) -> #DIV/0! | H17: =AVERAGE(H5:H16) -> #DIV/0! | I17: =AVERAGE(I5:I16) -> #DIV/0! | ... K17: =AVERAGE(K5:K16) -> #DIV/0!
C19: Лаборатория № 3: | G19: Лаборатория № 4
A20: Лаборанты хим.анализа:
A24: Коллектор отходящей воды: Массовая концентрация аммиака и ионов аммония в пересчёте на ион аммония, мг/дм3
A25: Дата: | B25: =B2 -> 0 | D25: Смена | E25: 2 | H25: Бригада
A27: Время | B27: 1059 | C27: 1-2гр. | D27: 3гр. | E27: 4гр. | F27: 4К | G27: отм.0.0 | H27: 12 | I27: 1859 | J27: 223А | K27: об.в.
A28: 0.33333333
A29: 0.375
A30: 0.41666667
A31: 0.45833333
A32: 0.5
A33: 0.54166667
A34: 0.58333333
A35: 0.625
A36: 0.66666667
A37: 0.70833333
A38: 0.75
A39: 0.79166667
A40: ср.знач. | B40: =AVERAGE(B28:B39) -> #DIV/0! | C40: =AVERAGE(C28:C39) -> #DIV/0! | D40: =AVERAGE(D28:D39) -> #DIV/0! | E40: =AVERAGE(E28:E39) -> #DIV/0! | F40: =AVERAGE(F28:F39) -> #DIV/0! | G40: =AVERAGE(G28:G39) -> #DIV/0! | H40: =AVERAGE(H28:H39) -> #DIV/0! | I40: =AVERAGE(I28:I39) -> #DIV/0! | ... K40: =AVERAGE(K28:K39) -> #DIV/0!
C42: Лаборатория № 3: | G42: Лаборатория № 4
A43: Лаборанты хим.анализа:

Sheet ПАК 
A1: ПЛАН АНАЛИТИЧЕСКОГО КОНТРОЛЯ
A2: производства бикарбоната натрия сырого
A3: Цех № 66 Отделения Абсорбции-Дистилляции-1, Карбонизации-1 | H3: 21.04.2025г.
A4: №№пп | B4: Наименование стадии процесса, места измерения параметров или отбора проб | C4: Контролируемый параметр | D4: Частота и способ контроля | E4: Норма и технологический показатель | F4: Метод испытания и средство контроля, НД | G4: Кто контролирует
A5: 1 | B5: 2 | C5: 3 | D5: 4 | E5: 5 | F5: 6 | G5: 7
A6: 1.Входной контроль
A7: 1.1. | B7: Аммиак водный технический марка А (аммиачная вода) | C7: Отборт проб | D7: Каждая партия | F7: ИОТ-Ц-66-23-2020 | G7: Аппаратчик
C8: Состав: Массовая доля аммиака (NH3), %, не менее | D8: Каждая партия | E8: 25 | F8: ГОСТ 9-92 | G8: Лаборатория № 4
A9: 1.2. | B9: Гидросульфид натрия технический, водный раствор | C9: Отборт проб | D9: Каждая партия | F9: ИОТ-Ц-66-23-2020 | G9: Аппаратчик
C10: Состав:Массовая доля гидросульфида натрия (NaHS), %, не менее | D10: Каждая партия | E10: 30 | F10: СТО 00204168-004-2009 «Гидросульфид натрия технический, водный раствор» (ТУ 20.13.41.110-008-43953934-2017) | G10: Лаборатория № 3
C11: Массовая доля сульфида натрия (Na2S),%, не более | D11: Проводится только при получении результатов по массовой доле гидросульфида натрия ниже нормативного значения | E11: 1
A12: 1.3. | B12: Натрия гидросульфид технический раствор отбор - с каждой ж/д или автоцистерны | C12: Отборт проб | D12: Каждая партия | F12: ИОТ-Ц-66-23-2020 | G12: Аппаратчик
C13: Массовая доля гидросульфида натрия %, не менее | D13: Каждая партия | E13: Сорт 1 - 27,0 Сорт 2 - 22,0 | F13: ТУ 20.13.41.110-008-43953934-2017 «Натрия гидросульфид технический раствор (натрий сернистый, кислый)» | G13: Лаборатория № 3
C14: Массовая доля сульфида натрия, %, не более | D14: Проводится только при получении результатов по массовой доле гидросульфида натрия ниже нормативного значения | E14: Сорт 1 - 1,5 Сорт 2 - 3,0
A15: 1.4. | B15: Гидросульфид натрия технический отбор - с каждой ж/д или автоцистерны | C15: Отборт проб | D15: Каждая партия | F15: ИОТ-Ц-66-23-2020 | G15: Аппаратчик
C16: Массовая доля гидросульфида натрия %, не менее | D16: Каждая партия | E16: 22 | F16: ТУ 2153-541-05763441-2012 «Гидросульфид натрия технический» | G16: Лаборатория № 3
C17: Массовая доля сульфида натрия, %, не более | D17: Проводится только при получении результатов по массовой доле гидросульфида натрия ниже нормативного значения | E17: 3
A18: 1.5 | B18: Рассол очищенный (для производства кальцинированной соды) | C18: Массовая (объёмно-эквивалентная) концентрация хлоридов в пересчёте на хлорид натрия (NaCl), г/дм3(н.д.), не менее | D18: 1 раз в смену 1 раз из усреднённой пробы за месяц | E18: 303,0 (103,6) | F18: МИ 74-А2-2017 (свидетельство об аттестации № 253.0122/RA.RU.311866 /2017) титриметрический метод Диапазон измерений от 250 до 318 г/дм3 | G18: Лаборатория № 4 Лаборатория ОТиВК
C19: Массовая (объёмно-эквивалентная) концентрация суммы кальция и магния в пересчёте на ион кальция, г/дм3(н.д.), не более | D19: 1 раз в смену 1 раз из усреднённой пробы за месяц | E19: 0,032 (0,032) | F19: МИ 75-А2-2017 (свидетельство об аттестации № 253.0111/RA.RU.311866 комплексонометрический метод Диапазон измерений от 0,010 до 1,00 г/дм3 | G19: Лаборатория № 4 Лаборатория ОТиВК
C20: Массовая (объёмно-эквивалентная) концентрация углекислого натрия (Na2СО3), г/дм3(н.д.), не более | D20: 1 раз из усреднённой пробы за месяц | E20: 0,80 (0,30) | F20: МИ 77-А2-2017 (свидетельство об аттестации № 253.0112/RA.RU.311866 /2017) титриметрический метод Диапазон измерений от 0,10 до 1,00 г/дм3 | G20: Лаборатория ОТиВК
C21: Плотность при 20 °С, г/см3, не менее | E21: Фактическое значение | F21: МИ 98-А2-2017 с использованием ареометра Диапазон измерений (1,180 – 1,240) г/см3
C22: Массовая (объёмно-эквивалентная) концентрация сульфат-ионов (SO42-), г/дм3/(н.д.), не более | E22: 4,00 (1,67) | F22: МИ 76-А2-017 (свидетельство об аттестации №253.0071/RA.RU.311866/20147) гравиметрический метод Диапазон измерений от 0,10 до 10,0 г/дм3
C23: Массовая (объёмно-эквивалентная) концентрация аммиака в пересчете на ион – аммония NH4+, мг/дм3/(н.д.), не более | E23: 5,00 (0,0055) | F23: МИ 78-А2-017 (свидетельство об аттестации № 253.0035/RA.RU.311866/2017) фотоколориметрический метод Диапазон измерений от 0,10 до 7,00 мг/дм3
C24: Массовая (объёмно-эквивалентная) концентрация гидроксид-ионов (ОН-), г/дм3, не более | E24: 0,060±0,017/ (0,070±0,020) | F24: МИ 102-А2-2017 Титриметрический метод Диапазон измерений (0,030 – 0,300) н.д.
A25: 2. Станция абсорбции
A26: 2.1 | B26: Промыватель воздуха фильтров поз.21-3 (ПВФл). Отбор пробы жидкости с трубопровода после аппарата,отм. 36.0 м | C26: Отбор проб | D26: 2 раза в смену | F26: ИОТ-Ц-66-08-2022 | G26: Аппаратчик
C27: Общая щелочность (прямой титр),г/дм3 (н.д.), не более | D27: 1 раз из усреднённой пробы за месяц 2 раза в смену | E27: 3,6 (4,0) | F27: МИ 115-А2-2019 Титриметрический метод Диапазон измерений - в жидкостях 1,0 до 300,0 н.д. включительно ИОТ-Ц-66-08-2022 | G27: Лаборатория № 3 Аппаратчик
C28: Массовая (объёмно-эквивалентная) концентрация хлорид-ионов, г/дм3 /(н.д.) | D28: 1 раз из усреднённой пробы за месяц | E28: Фактическое значение | F28: МИ 85-А2-2017 Титриметрический метод Диапазон измерений (0,040 – 106,0) н.д. | G28: Лаборатория № 3
C29: Массовая (объёмно-эквивалентная) концентрация двуокиси углерода, г/дм3 /(н.д.) | D29: 1 раз из усреднённой пробы за месяц | E29: Фактическое значение | F29: МИ 79-А2-2017 Газо-объёмный метод Диапазон измерений (0,020 – 200,0) н.д. | G29: Лаборатория № 3
A30: 2.2 | B30: Промыватель воздуха фильтров. поз.21-3 (ПВФл) Замер на коллекторе нагнетания после поз.61-5 (ТВН-360-22-1) вакуумной станции цеха Компрессии отм. 4.0 м | C30: Отбор проб | D30: 1 раз в смену | F30: ИОТ-Ц-50-18-2023 МИ 139-А2-2020 | G30: Лаборатория № 3 в присутствии аппаратчика
C31: Массовая концентрация аммиака в газе, выходящем из ПВФл и расчет потерь аммиака с газом на 1 т соды (в пересчёте на аммиачную воду с массовой долей 25,5 %), кг/т соды, не более | D31: 1 раз в смену | E31: 0.8 | F31: МИ 139-А2-2020 Колориметрический метод | G31: Лаборатория № 3
A32: 2.3 | B32: Второй промыватель газа колонн поз. 91-7 (ПГКл-II) Отбор пробы жидкости с трубопровода аппарата,отм.28.0 м | C32: Отбор проб | D32: 2 раза в смену | F32: ИОТ-Ц-66-08-2022 | G32: Аппаратчик
C33: Общая щелочность (прямой титр),г/дм3 (н.д.), не более | D33: 1 раз в декаду 2 раза в смену | E33: 21,6 (24,0) | F33: МИ 115-А2-2019 Титриметрический метод Диапазон измерений: - в жидкостях 1,0 до 300,0 н.д. включительно | G33: Лаборатория № 3 Аппаратчик
C34: Массовая (объёмно-эквивалентная) концентрация хлорид-ионов, г/дм3 /(н.д.) | D34: 1 раз из усреднённой за месяц пробы | E34: Фактическое значение | F34: МИ 85-А2-2017 Титриметрический метод Диапазон измерений (0,040 – 106,0) н.д. | G34: Лаборатория № 3
C35: Массовая (объёмно-эквивалентная) концентрация двуокиси углерода, г/дм3 /(н.д.) | D35: 1 раз из усреднённой пробы за месяц | E35: Фактическое значение | F35: МИ 79-А2-2017 Газо-объёмный метод Диапазон измерений (0,020 – 200,0) н.д. | G35: Лаборатория № 3
A36: 2.4 | B36: Второй промыватель газа колонн поз.91-7( ПГКл-II).Замер газа на трубопроводе после аппарата отм. 40.0 м | C36: Отбор проб | D36: 1 раз в сутки | F36: ИОТ-Ц-50-18-2023 МИ 15-А2-2016 | G36: Лаборатория № 3 в присутствии аппаратчика
C37: Объёмная доля углекислого газа, % (об.), не более | D37: 1 раз в сутки | E37: 8 | F37: МИ 15-А2-2016 Газообъемный метод . Диапазон измерений по углекислому газу (0,2 – 99,0) % | G37: Лаборатория № 3
C38: Отбор проб | D38: 1 раз в смену | F38: ИОТ-Ц-50-18-2023 МИ 139-А2-2020 | G38: Лаборатория № 3 в присутствии аппаратчика
C39: Массовая концентрация аммиака в газе, выходящем из ПГКл-2 и расчет потерь аммиака с газом на 1 т соды (в пересчёте на аммиачную воду с массовой долей 25,5 %), кг/т соды, не более | D39: 1 раз в смену | E39: 0.8 | F39: МИ 139-А2-2020 Колориметрический метод | G39: Лаборатория № 3
A40: 2.5 | B40: Промыватель газа абсорбции поз.31-3 (ПГАБ) Отбор проб жидкости с трубопровода после аппарата отм. 32.0 м | C40: Отбор проб | D40: 2 раза в смену | F40: ИОТ-Ц-66-08-2022 | G40: Аппаратчик
...

Sheet Техкарта 
A1: ТЕХНИЧЕСКАЯ КАРТА по контролю ведения технологического режима производства бикарбоната натрия сырого цеха № 66 отделений Абсорбции-дистилляции-1, Карбонизация-1
H3: 23.04.2025г.
A4: № п/п | B4: Что контролируется | C4: Контролируемые параметры | D4: Нормы | F4: Частота контроля | G4: Кто контролирует
D5: По регламенту | E5: По техрежиму
A6: 1 | B6: 2 | C6: 3 | D6: 4 | E6: 5 | F6: 6 | G6: 7
A7: 1. | B7: Промыватель воздуха фильтров поз.21-3 (ПВФл). Замер на коллекторе нагнетания после поз.6 1-5(ТВН-360-22-1) вакуумной станции цеха Компрессии отм. 4.0 м | C7: Массовая концентрация аммиака в газе, выходящем из ПГКл-2 и расчет потерь аммиака с газом на 1 т соды (в пересчёте на аммиачную воду с массовой долей 25,5 %), кг/т соды, не более | D7: 0.8 | E7: 0.8 | F7: 1 раз в смену | G7: Лаборатория № 3
A8: 2. | B8: Второй промыватель газа колонн поз. 91-7 (ПГКл-II) Отбор пробы жидкости с трубопровода аппарата, отм.28.0 м Замер газа на трубопроводе после аппарата, отм.40.0 м | C8: Общая щелочность (прямой титр), г/дм3 (н.д.), не более | D8: 21,6 (24,0) | E8: 21,6 (24,0) | F8: 1 раз в декаду | G8: Лаборатория № 3
C9: Объёмная доля углекислого газа, % (об.), не более | D9: 8 | E9: 8 | F9: 1 раз в сутки | G9: Лаборатория № 3
C10: Массовая концентрация аммиака в газе, выходящем из ПГКл-2 и расчет потерь аммиака с газом на 1 т соды (в пересчёте на аммиачную воду с массовой долей 25,5 %), кг/т соды, не более | D10: 0.8 | E10: 0,20у | F10: 1 раз в смену | G10: Лаборатория № 3
A11: 3. | B11: Промыватель газа абсорбции. поз.31-3 (ПГАБ) Замер газа с коллектора отд. Карбонизация-1 отм. 17.0 м Отбор проб жидкости с трубопровода после аппарата отм. 32.0 м | C11: Объёмная доля углекислого газа, % (об.), не менее | D11: 90 | E11: 90 | F11: 2 раза в смену | G11: Лаборатория № 3
C12: Общая щелочность (прямой титр), г/дм3 (н.д.), не более | D12: 36,1 (40,0) | E12: 36,1 (40,0) | F12: 1 раз в декаду | G12: Лаборатория № 3
A13: 4. | B13: Холодильник газа дистилляции поз.81-7 (ХГДС) | C13: Температура газа ХГДС на выходе, °С | D13: 56÷62 | E13: 56÷62 | F13: 2 раза в смену | G13: Лаборатория № 3
A14: 5. | B14: Сборник аммонизированного рассола (САР) поз.151,2 Отбор проб с коллектора отм.12.0 м; 22.0 м | C14: Общая щелочность (прямой титр), г/дм3 (н.д.) | D14: Летом (90,2÷93,8)/ (100,0÷104,0) Зимой (92,0÷95,6)/ (102,0÷106,0) | E14: Летом (90,2÷93,8)/ (100,0÷104,0) Зимой (92,0÷95,6)/ (102,0÷106,0) | F14: 10-12 раз в смену | G14: Лаборатория № 3
C15: Массовая (объёмно-эквивалентная) концентрация хлорид-ионов, г/дм3/(н.д.), не менее | D15: 153,9 (86,8) | E15: 153,9 (86,8) | F15: 2 раза в смену и из усредненной пробы за смену | G15: Лаборатория № 3
C16: Массовая (объёмно-эквивалентная) концентрация сульфид-ионов, г/дм3 (н.д.) | D16: 0,16÷0,80 (0,20÷1,00) | E16: 0,16÷0,80 (0,20÷1,00) | F16: 2 раза в смену | G16: Лаборатория № 3
C17: Температура жидкости,°С, не более | D17: 70 | E17: 70 | F17: 2 раза в смену | G17: Лаборатория № 3
A18: 6. | B18: Конденсатор газа дистилляции (КДС) поз.331-7 | C18: Температура газ на выходе из аппарата, °С, не более | D18: 71 | E18: 71 | F18: 2 раза в смену | G18: Лаборатория № 3
A19: 7. | B19: Коллектор жидкости после дистиллера слабой жидкости (ДСЖ) поз.44 и поз.77 (ДСЖ № 1,2) отм. 0.0 м | C19: Массовая (объёмно-эквивалентная) концентрация аммиака, г/дм3/(н.д.; н.д./2л), не более | D19: 0,17/(0,20; 20,0) | E19: 0,17/(0,20; 20,0) | F19: 1 раз в смену и из усредненной пробы за смену | G19: Лаборатория № 3
A20: 8. | B20: Коллектор жидкости после испарителя поз.401-7 (ИС) отм.0.0 м | C20: Массовая (объёмно-эквивалентная) концентрация аммиака, г/дм3/(н.д.; н.д./2л), не более | D20: 0,13 (0,15; 15,0) | E20: 0,13 (0,15; 15,0) | F20: 1 раз в смену с каждого элемента и из усредненной пробы за смену | G20: Лаборатория № 3
C21: Массовая (объемно-эквивалентная ) концентрация активного гидроксида кальция в пересчёте на активную окись кальция (СаОакт), г/дм3/(н.д.), не более | D21: 3,5 (2,5) | E21: 3,5 (2,5) | F21: 1 раз в смену с каждого элемента и из усредненной пробы за смену | G21: Лаборатория № 3
C22: Массовая (объёмно-эквивалентная) концентрация хлорид-ионов, г/дм3/(н.д.), не менее | D22: 106,4 (60,0) | E22: 106,4 (60,0) | F22: 1 раз в смену с каждого элемента и из усредненной пробы за смену | G22: Лаборатория № 3
A23: 9. | B23: Коллектор жидкости после теплообменника дистилляции поз. 341-7 (ТДС) отм. 16.0 м | C23: Массовая (объёмно-эквивалентная) концентрация двуокиси углерода, г/дм3/(н.д.), не более | D23: 2,20 (2,00) | E23: 2,20 (2,00) | F23: 1 раз в смену с каждого элемента | G23: Лаборатория № 3
A24: 10. | B24: Коллектор суспензии гидрокарбоната натрия с карбоколонн на группу барабанных вакуум-фильтров поз.5812-19 отм. 8.0 м и ленточные фильтры поз.F201, поз.F401 отм.12.0 м | C24: Массовая (объёмно-эквивалентная) концентрация NH3связ, г/дм3/(н.д.), не менее | D24: Летом: 61,3 (68,0) Зимой: 63,1 (70,0) | E24: Летом: 63,1 (71,0)у Зимой: 64,9 (72,0)у | F24: 2 раза в смену с ленточных фильтров и группы колонн с барабанных фильтров и из усредненных проб за смену | G24: Лаборатория № 3
C25: Массовая (объёмно-эквивалентная) концентрация хлорид-ионов, г/дм3 /(н.д.), не менее | D25: 168,4 (95,0) | E25: 168,4 (95,0) | F25: 1-2 раза в смену с ленточных фильтров и группы колонн с барабанных фильтров и из усредненных проб за смену | G25: Лаборатория № 3
C26: Температура суспензии на выходе из колонны, °С | D26: 25÷36 | E26: 25÷36 | F26: 2 раза в смену | G26: Лаборатория № 3
C27: Температура газа на выходе из колонны, °С | D27: 42÷52 | E27: 42÷52 | F27: 2 раза в смену | G27: Лаборатория № 3
A28: 11. | B28: Колонна предварительной карбонизации (КлПК) поз.51, отм. 12.0 м | C28: Массовая (объёмно-эквивалентная) концентрация двуокиси углерода, г/дм3/(н.д.), не более | D28: 60,5÷74,8 (55,0÷68,0) | E28: 60,5÷74,8 (55,0÷68,0) | F28: 2 раза в смену | G28: Лаборатория № 3
A29: 12. | B29: Сырой гидрокарбонат натрия с барабанных вакуум-фильтров поз.5812÷19, отм. 8.0 м | C29: Массовая доля влаги, при выпуске соды с содержанием Cl- не более 0,15%,%, не более | D29: 17 | E29: 17 | F29: 4-6 раз в смену с группы вакуум фильтров | G29: Лаборатория № 3
C30: при выпуске соды 1 сортом с содержанием Cl- не более 0,5%,%, не более | D30: 17 | E30: 17 | G30: Лаборатория № 3
C31: Массовая доля хлоридов в пересчёте на хлорид натрия, при выпуске соды с содержанием Cl- не более 0,15%,%, не более | D31: 0.08 | E31: 0.08 | F31: 12 раз в смену с каждого фильтра (10 раз в смену с каждого фильтра и 2 раза в смену с группы фильтров) | G31: Лаборатория № 3
C32: при выпуске соды 1 сортом с содержанием Cl- не более 0,5%,%, не более | D32: 0.4 | E32: 0,18 – 0,25у | G32: Лаборатория № 3
A33: 13. | B33: Сырой гидрокарбонат натрия с ленточных вакуум-фильтров поз.F-201, поз.F-401, отм. 8.0 м | C33: Массовая доля влаги, при выпуске соды с содержанием Cl- не более 0,15%,%, не более | D33: 16.8 | E33: 16.8 | F33: 4-6 раз в смену с каждого фильтра | G33: Лаборатория № 3
C34: при выпуске соды 1 сортом с содержанием Cl- не более 0,5%,%, не более | D34: 16.8 | E34: 16.8 | G34: Лаборатория № 3
C35: Массовая доля хлоридов в пересчёте на хлорид натрия, при выпуске соды с содержанием Cl- не более 0,15%,%, не более | D35: 0.08 | E35: 0.08 | F35: 12 раз в смену с каждого фильтра | G35: Лаборатория № 3
C36: при выпуске соды 1 сортом с содержанием Cl- не более 0,5%,%, не более | D36: 0.25 | E36: 0,18 – 0,25у | G36: Лаборатория № 3
A37: 14. | B37: Коллектор маточной жидкости с каждого ленточного фильтра поз.F-201, поз.F-401, отм. 0.0 м | C37: Потери гидрокарбоната натрия, при выпуске соды с содержанием Cl- не более 0,15%, %, не более | D37: 3.5 | E37: 3.5 | F37: 1 раз в смену | G37: Лаборатория № 3
C38: при выпуске соды 1 сортом с содержанием Cl- не более 0,5%,%, не более | D38: 2.8 | E38: 2.8 | G38: Лаборатория № 3
C39: Массовая (объёмно-эквивалентная) концентрация хлорид-ионов, при выпуске соды с содержанием Cl- не более 0,15%, г/дм3 (н.д.), не менее | D39: 161,3 (91,0) | E39: 163,1 (91,0) | F39: 2-3 раза в смену с каждого фильтра и 1 раз из усредненной пробы с каждого фильтра за смену | G39: Лаборатория № 3
C40: при выпуске соды 1 сортом с содержанием Cl- не более 0,5%,%, не менее | D40: 164,9 (93,0) | E40: 163,3 (92,0)у | G40: Лаборатория № 3
A41: 15. | B41: Коллектор маточной жидкости с группы барабанных вакуум-фильтров поз.5812-19, отм. 0.0 м | C41: Потери гидрокарбоната натрия, при выпуске соды с содержанием Cl- не более 0,15%, %, не более | D41: 10 | E41: 10 | F41: 1 раз в смену | G41: Лаборатория № 3
...

Sheet Авт.контроль
A1: Перечень параметров автоматического контроля, фиксируемых в Листах результатов контроля технологического режима цеха № 66 (отделений Абсорбции-дистилляции-1, Карбонизации-1), цеха № 83 (отделения Кальцинации-1), цеха № 85 (отделения Компрессии-1)
A2: № п/п | B2: Наименование стадий процесса, места измерения параметров или отбора проб | C2: Контролируемый параметр | D2: Норма и технический показатель | E2: Частота и способ контроля | F2: Нормативный документ | G2: Способ контроля | H2: 22.04.2025г
A3: 1 | B3: 2 | C3: 3 | D3: 4 | E3: 5 | F3: 6 | G3: 7
A4: Цех № 66
A5: Отделение Абсорбции-Дистилляции-1
A6: Станция абсорбции
A7: 1 | B7: Коллектор оборотной воды | C7: Температура, °С | D7: 20-28 | E7: 1 раз в смену | F7: Данный показатель фиксируется в качестве дополнительных сведений для ведения технологического режима | G7: Сведения с АСУТП
A8: 2 | B8: Трубопровод подачи очищенного рассола в отделение АД-1 | C8: Расход, м3/за смену | D8: факт | E8: 1 раз в смену | F8: ТР 03-2025 | G8: По телефонной связи с технологическим персоналом
A9: 3 | B9: Трубопровод газовой смеси на выходе из холодильника газа дистилляции поз. 81,2,3,5,7 (ХГДС) | C9: Температура, °С | D9: 56-62 | E9: 2 раза в смену | F9: ТР 03-2025/ Техническая карта по контролю ведения технологического режима цеха № 66 | G9: Сведения с АСУТП
A10: 4 | B10: Трубопровод выхода газа из нижней части второго абсорбера поз. 122,3,5 (АБ-II) | C10: Температура, °С | D10: 56-62 | E10: 2 раза в смену | F10: ТР 03-2025 | G10: Сведения с АСУТП
A11: 5 | B11: Сборник аммонизированного рассола (САР) поз.151,2 | C11: Уровень, м3 | D11: 120-700 | E11: 1 раз в смену | F11: ТР 03-2025 | G11: По телефонной связи с технологическим персоналом
A12: 6 | B12: Трубопровод подачи аммонизированного рассола в отделение Карбонизации-1 | C12: Температура,°С, не более | D12: 70 | E12: 1 раз в смену | F12: ТР 03-2025/ Техническая карта по контролю ведения технологического режима цеха № 66 | G12: Сведения с АСУТП
A13: 7 | B13: Трубопровод газовой смеси на выходе из первого абсорбера поз. 111,7 (АБ-I) | C13: Температура, °С | D13: 56-62 | E13: 2 раза в смену | F13: ТР 03-2025 | G13: Сведения с АСУТП
A14: 8 | B14: Трубопровод подачи очищенной воды с установки использования тепла дистиллерной жидкости (УИТДЖ) и с ТЭЦ на всас насоса поз.141-4 | C14: Расход, м3/за смену | D14: факт | E14: 1 раз в смену | F14: ТР 03-2025 | G14: По телефонной связи с технологическим персоналом
A15: Станция дистилляции
A16: 9 | B16: Сборник фильтровой жидкости поз.291,2 | C16: Уровень, м3 | D16: 300-800 | E16: 1 раз в смену | F16: ТР 03-2025 | G16: По телефонной связи с технологическим персоналом
A17: 10 | B17: Трубопровод подачи фильтровой жидкости на элементы дистилляции № 1÷3,4,5÷7 | C17: Расход, м3/ч | D17: 100-190 | E17: 2 раза в смену | F17: ТР 03-2025 | G17: Сведения с АСУТП
A18: 11 | C18: Расход, м3/за смену | D18: факт | E18: 1 раз в смену | F18: ТР 03-2025 | G18: По телефонной связи с технологическим персоналом
A19: 12 | B19: Трубопровод газовой смеси на выходе из КДС поз. 331-3,4,5-7 | C19: Температура, °С, не более | D19: 71 | E19: 2 раза в смену | F19: ТР 03-2025/ Техническая карта по контролю ведения технологического режима цеха № 66 | G19: Сведения с АСУТП
A20: 13 | B20: Трубопровод газовой смеси на выходе из дистиллера поз. 351,4,2,3,5-7 | C20: Температура, °С | D20: 92-100 | E20: 2 раза в смену | F20: ТР 03-2025 | G20: Сведения с АСУТП
A21: 14 | B21: Дистиллер поз. 351,4,2,3,5-7 | C21: Давление в нижней зоне, кгс/см2, не более | D21: 0.5 | E21: 2 раза в смену | F21: ТР 03-2025 | G21: Сведения с АСУТП
A22: 1 | B22: 2 | C22: 3 | D22: 4 | E22: 5 | F22: 6 | G22: 7
A23: Отделение Карбонизации-1
A24: Станция Карбонизации
A25: 15 | B25: Трубопровод речной воды | C25: Температура, °С | D25: 4-28 | E25: 1 раз в смену | F25: ТР 03-2025 | G25: Сведения с АСУТП
A26: 16 | B26: Колонна карбонизации поз. 551-5, 6, 7-10, 12-15 (режим осадительной колонны) | C26: Температура 25-ой бочки, °С | D26: 58-60 | E26: 2 раза в смену | F26: ТР 03-2025 | G26: Сведения с АСУТП
A27: 17 | B27: Колонна карбонизации поз. 551-5, 6, 7-10, 12-15 (режим осадительной колонны) | C27: Температура 14-ой бочки, °С, не менее | D27: 60 | E27: 2 раза в смену | F27: ТР 03-2025 | G27: Сведения с АСУТП
A28: 18 | B28: Трубопровод суспензии после карбоколонны поз. 551-5 ,6, 7-10, 12-15 | C28: Температура, °С | D28: 25-36 | E28: 2 раза в смену | F28: ТР 03-2025/ Техническая карта по контролю ведения технологического режима цеха № 66 | G28: Сведения с АСУТП
A29: 19 | B29: Трубопровод отходящего газа после карбоколонны поз.551-5, 6, 7-10, 12-15 | C29: Температура, °С | D29: 42-52 | E29: 2 раза в смену | F29: ТР 03-2025/ Техническая карта по контролю ведения технологического режима цеха № 66 | G29: Сведения с АСУТП
A30: 20 | B30: Трубопровод 2-ой жидкости из поз.521-3 ПГКл-1,2,3 группы карбоколонн | C30: Температура, °С | D30: 38-40 | E30: 1 раз в смену | F30: ТР 03-2025 | G30: Сведения с АСУТП
A31: 21 | B31: Колонна карбонизации поз.551-5, 6, 7-10, 12-15 (Режим предварительной карбонизации) | C31: Температура, °С | D31: факт | E31: 1 раз в смену | F31: «Методика по заполнения формы технического отчета Производства кальцинированной соды № 39699/203/13», Распоряжение от 31.01.2014 г. № 83 | G31: По телефонной связи с технологическим персоналом
A32: Станция Фильтрации
A33: 22 | B33: Трубопровод промывной воды | C33: Температура, °С | D33: 30-40 | E33: 1 раз в смену | F33: ТР 03-2025/ Техническая карта по контролю ведения технологического режима цеха № 66 | G33: Сведения с АСУТП
A34: 23 | B34: Третья ступень промывки ленточного фильтра | C34: Расход, м3/за смену | D34: факт | E34: 1 раз в смену | F34: ТР 03-2025 | G34: Сведения с АСУТП
A35: Станция охлаждения и промывки газа содовых печей (паровых кальцинаторов)
A36: 24 | B36: Коллектор вакуума | C36: Давление, мм.рт.ст., не более | D36: минус 220 | E36: 12 раз в смену | F36: ТР 03-2025/ Техническая карта по контролю ведения технологического режима цеха № 66 | G36: Сведения с АСУТП
A37: 25 | B37: Трубопровод газа на выходе из ХГСП (ХГПК) поз. 691-5 | C37: Температура, °С | D37: 40-50 | E37: 2 раза в смену | F37: ТР 03-2025 | G37: Сведения с АСУТП
B38: Перечень составил: | D38: А.З.Краснова | E38: Дата: 22.04.2025г.
B39: Начальник лаборатории № 3 | D39: Э.С.Михайлова
B41: Актуализация перечня по мере изменений в нормативных документах

Sheet Обозначения и сокращения
A1: Обозначения и сокращения в соответствии с Планом аналитического контроля производства бикарбоната натрия сырого ( Цех№ АДК-1. Отделение АД-1, Карбонизация -1) | D1: Обозначения и сокращения используемые в листах результатов контроля технологического режима
A2: № п/п | B2: Наименование сокращений | C2: Расшифровка | D2: № п/п | E2: Наименование сокращений | F2: Расшифровка
A3: 1 | B3: ПВФЛ | C3: Промыватель воздуха фильтров | D3: 1 | E3: МЖ | F3: Маточная жидкость
A4: 2 | B4: ПГКЛ-II | C4: Второй промыватель газа колонн | D4: 2 | E4: ФЖ | F4: фильтровая жидкость
A5: 3 | B5: ПГАБ | C5: Промыватель газа абсорбции | D5: 3 | E5: б/ф | F5: Барабанный вакуум-фильтр
A6: 4 | B6: САР | C6: Сборник аммонизированного рассола | D6: 4 | E6: л/ф | F6: ленточный вакуум-фильтр
A7: 5 | B7: КЛПК | C7: Колонна предварительной карбонизации | D7: 6 | E7: гр. | F7: Группа
A8: 6 | B8: ПГКЛ-I | C8: Первый промыватель газа колонн | D8: 7 | E8: М.к. | F8: Массовая концентрация
A9: 7 | B9: СФЖ | C9: Сборник фильтровой жидкости | D9: 8 | E9: М.д. | F9: Массовая доля
A10: 8 | B10: КЛ | C10: Карбонизационная колонна | D10: 9 | E10: Об.-экв.к. | F10: объёмно-эквивалентная концентрация
A11: 9 | B11: ИС | C11: Испаритель | D11: 10 | E11: в/ф | F11: вакуум-фильтр
A12: 10 | B12: ДС | C12: Дистиллер | D12: 11 | E12: конц.,к. | F12: Концентрация
A13: 11 | B13: ДСЖ | C13: Дистиллер слабой жидкости | D13: 12 | E13: двуок.угл. | F13: двуокись углерода
A14: 12 | B14: ТДС | C14: Теплообменник дистилляции | D14: 13 | E14: гидрокс.кальц.в пер.на акт.окись кальц. (СаОакт) | F14: активный гидроксид кальция в пересчёте на активную окись кальция (СаОакт)
... A21: 19 | B21: АБ1/АБ2 | C21: абсорбер 1/ абсорбер 2 | D21: 20 | E21: н.тех.п | F21: нет технологического персонала
D22: 21 | E22: н.св | F22: Нет света
D23: 22 | E23: н.ж | F23: Нет жидкости
D24: 23 | E24: н.п | F24: Нет подхода
D25: 24 | E25: рем.р | F25: Ремонтные работы
D26: 25 | E26: доп. анализы | F26: Дополнительные анализы
D27: 26 | E27: отм. | F27: Отметка
D28: 27 | E28: ср.зн. | F28: Среднее значение
A29: Обозначения и сокращения единиц измерения | D29: 28 | E29: уср.проба за см. | F29: Усреднённая проба проба
A30: № п/п | B30: Наименование сокращений | C30: Расшифровка | D30: 29 | E30: ап. | F30: Аппаратчик
A31: 1 | B31: н.д. | C31: нормальные деления | D31: 30 | E31: лаб. | F31: Лаборант
A32: 2 | B32: н.д./2л | C32: нормальные деления на 2 литра | D32: 31 | E32: м.см. | F32: мастер смены
A33: 3 | B33: кг/т.с. | C33: килограмм на тонну соды | D33: 32 | E33: акт.окись | F33: Активная окись
A34: 4 | B34: м3/ч | C34: метр кубический в час | D34: 33 | E34: ком.отб | F34: Комиссионный отбор
A35: 5 | B35: м3 | C35: метр кубический | D35: 34 | E35: бик-т натр. | F35: Бикарбонат натрия
A36: 6 | B36: 0С | C36: градус Цельсия | D36: 35 | E36: прав | F36: Правый
A37: 7 | B37: кгс/см2 | C37: килограмм силы на квадратный сантиметр | D37: 36 | E37: лев | F37: Левый
A38: 8 | B38: мм.рт.ст | C38: миллиметр ртутного столба | D38: 37 | E38: датч | F38: Датчик
A39: 9 | B39: % | C39: проценты | D39: 38 | E39: сер | F39: Середина
A40: 10 | B40: мг/дм3 | C40: миллиграм на кубический дециметр | D40: 39 | E40: южн | F40: Южный
A41: 11 | B41: % (об.) | C41: концентрация газа в объемных процентах | D41: 40 | E41: сев | F41: Северный
A42: 12 | B42: Па | C42: Паскаль | D42: 41 | E42: зап | F42: Западный
D43: 42 | E43: вост | F43: Восточный
D44: 43 | E44: Рн | F44: Давление низа
D45: 44 | E45: ам.вода | F45: Амиачная вода
D46: 45 | E46: об.в | F46: Оборотная вода
...

Sheet Качеств.показатели
A1: Дата | B1: Смена | C1: Отх. газ после ПВФл | F1: Жидк. после ПГКл-2 | I1: Отходящий газ после ПГКл-2 | P1: Отх.газ после ПГАБ | S1: Жидк. после ПГАБ | V1: Газ после ХГДС | Y1: Аммонизировнный рассол | AK1: Газ после КДС | AN1: Жидк. после ДСЖ | AQ1: Жидкость после испарителя | AZ1: Жидкость после ТДС | BC1: Суспензия гидрокарбонатат натрия | BP1: Жидк.после КЛПК | BS1: Сырой гидрокарбонат натрия с б/ф | BY1: Маточная жидкость с б/ф | CE1: Сырой гидрокарбонат натрия с л/ф | CK1: Маточная жидкость с л/ф | CQ1: Промывная вода | CZ1: Вакуум в/ф
C2: М.к. аммиака | D2: кол-во ан. | E2: кол-во откл. | F2: Общ.щ. | G2: кол-во ан. | H2: кол-во откл. | I2: Об.доля СО₂ | J2: кол-во ан. | K2: кол-во откл. | L2: М.к. аммиака | M2: кол-во ан. | N2: кол-во откл. | O2: кол-во откл.по ТК | P2: Об.доля СО₂ | Q2: кол-во ан. | R2: кол-во откл. | S2: Общ.щ. | T2: кол-во ан. | U2: кол-во откл. | V2: Тем-ра | W2: кол-во ан. | X2: кол-во откл. | Y2: Общ.щ. | Z2: кол-во ан. | AA2: кол-во откл. | AB2: Об.экв.к. Cl⁻ | AC2: кол-во ан. | AD2: кол-во откл. | AE2: Об.экв.к. S²⁻ | AF2: кол-во ан. | AG2: кол-во откл. | AH2: Тем-ра | AI2: кол-во ан. | AJ2: кол-во откл. | AK2: Тем-ра | AL2: кол-во ан. | AM2: кол-во откл. | AN2: Об.экв.к.NH₃ | AO2: кол-во ан. | AP2: кол-во откл. | AQ2: Об.экв.к.NH₃ | AR2: кол-во ан. | AS2: кол-во откл. | AT2: Об.экв.к.CаО | AU2: кол-во ан. | AV2: кол-во откл. | AW2: Об.экв.к. Cl⁻ | AX2: кол-во ан. | AY2: кол-во откл. | AZ2: Об.экв.к. СО₂ | BA2: кол-во ан. | BB2: кол-во откл. | BC2: Об.экв.к.св. NH₃ | BD2: кол-во ан. | BE2: кол-во откл. | BF2: кол-во откл.по ТК | BG2: Об.экв.к. Cl⁻ | BH2: кол-во ан. | BI2: кол-во откл. | BJ2: Тем-ра | BK2: кол-во ан. | BL2: кол-во откл. | BM2: Тем-ра | BN2: кол-во ан. | BO2: кол-во откл. | BP2: Об.экв.к. СО₂ | BQ2: кол-во ан. | BR2: кол-во откл. | BS2: М.д. влаги | BT2: кол-во ан. | BU2: кол-во откл. | BV2: М.д.хлоридов | BW2: кол-во ан. | BX2: кол-во откл. | BY2: П б-та | BZ2: кол-во ан. | CA2: кол-во откл. | CB2: Об.экв.к. Cl⁻ | CC2: кол-во ан. | CD2: кол-во откл. | CE2: М.д. влаги | CF2: кол-во ан. | CG2: кол-во откл. | CH2: М.д.хлоридов | CI2: кол-во ан. | CJ2: кол-во откл. | CK2: П б-та | CL2: кол-во ан. | CM2: кол-во откл. | CN2: Об.экв.к. Cl⁻ | CO2: кол-во ан. | CP2: кол-во откл. | CQ2: Тем-ра | CR2: кол-во ан. | CS2: кол-во откл. | CT2: Об.экв.к. Cl⁻ | CU2: кол-во ан. | CV2: кол-во откл. | CW2: Общ.щ. | CX2: кол-во ан. | CY2: кол-во откл. | CZ2: Вакуум в/ф | DA2: кол-во ан. | DB2: кол-во откл.
C3: не более 0,80 кг/ т.с | F3: не более 24,0 н.д | I3: не более 8,0 н.д | L3: не более 0,80 кг/т.с | O3: н.б. 0,20 кг/т.с. | P3: не менее 90,0 % | S3: не более 40,0 н.д | V3: 56-62 ⁰С | Y3: 102,0-106,0 н.д | AB3: не менее 86,8 н.д | AE3: 0,20-1,00 н.д | AH3: не более 70⁰С | AK3: не более 71 ⁰С | AN3: не более 20,0 н.д/2л | AQ3: не более 15,0 н.д/2л | AT3: не более 2,5 н.д | AW3: не менее 60,0 н.д | AZ3: не более 2,00 н.д | BC3: не менее 70,0 н.д. | BF3: н.м.72,0 | BG3: не менее 95,0 н.д | BJ3: 25-36 ⁰С | BM3: 42-52 ⁰С | BP3: 55,0-68,0 н.д | BS3: не более 17,0 % | BV3: не более 0,08 % | BY3: не более 10,0 % | CB3: не менее 82,0 н.д | CE3: не более 16,8 % | CH3: не более 0,08 % | CK3: не более 3,5 % | CN3: не менее 91,0 н.д | CQ3: 30-40 ⁰С | CT3: не более 0,30 н.д | CW3: не более 25,0 н.д | CZ3: не менее 220 мм.рт.ст.
